2020-11-25 19:35:57,590 INFO    MainThread:319870 [wandb_init.py:_log_setup():292] Logging user logs to wandb/offline-run-20201125_193557-268gyzhk/logs/debug.log
2020-11-25 19:35:57,590 INFO    MainThread:319870 [wandb_init.py:_log_setup():293] Logging internal logs to wandb/offline-run-20201125_193557-268gyzhk/logs/debug-internal.log
2020-11-25 19:35:57,590 INFO    MainThread:319870 [wandb_setup.py:_flush():68] setting env: {'api_key': '21c78eafd4fee542c98beb82cab2ea36505fdc41', 'mode': 'dryrun'}
2020-11-25 19:35:57,590 INFO    MainThread:319870 [wandb_setup.py:_flush():68] setting user settings: {}
2020-11-25 19:35:57,591 INFO    MainThread:319870 [wandb_setup.py:_flush():68] multiprocessing start_methods=fork,spawn,forkserver
2020-11-25 19:35:59,366 INFO    MainThread:319870 [wandb_run.py:_console_start():1265] atexit reg
2020-11-25 19:35:59,369 INFO    MainThread:319870 [wandb_run.py:_redirect():1135] redirect: SettingsConsole.REDIRECT
2020-11-25 19:35:59,369 INFO    MainThread:319870 [wandb_run.py:_redirect():1138] Redirecting console.
2020-11-25 19:35:59,369 INFO    MainThread:319870 [redirect.py:install():196] install start
2020-11-25 19:35:59,370 INFO    MainThread:319870 [redirect.py:install():211] install stop
2020-11-25 19:35:59,370 INFO    MainThread:319870 [redirect.py:install():196] install start
2020-11-25 19:35:59,392 INFO    MainThread:319870 [redirect.py:install():211] install stop
2020-11-25 19:35:59,392 INFO    MainThread:319870 [wandb_run.py:_redirect():1182] Redirects installed.
2020-11-25 19:35:59,392 INFO    MainThread:319870 [wandb_run.py:_config_callback():581] config_cb None None {'_wandb': {'cli_version': '0.10.5', 'python_version': '3.8.5', 'is_jupyter_run': False, 'is_kaggle_kernel': False, 'framework': 'torch'}}
2020-11-25 19:36:21,504 ERROR   Thread-1  :319870 [retry.py:__call__():111] Retry attempt failed:
Traceback (most recent call last):
  File "/home/mvpavlukhin/.conda/envs/speech2face/lib/python3.8/site-packages/urllib3/connection.py", line 159, in _new_conn
    conn = connection.create_connection(
  File "/home/mvpavlukhin/.conda/envs/speech2face/lib/python3.8/site-packages/urllib3/util/connection.py", line 84, in create_connection
    raise err
  File "/home/mvpavlukhin/.conda/envs/speech2face/lib/python3.8/site-packages/urllib3/util/connection.py", line 74, in create_connection
    sock.connect(sa)
socket.timeout: timed out

During handling of the above exception, another exception occurred:

Traceback (most recent call last):
  File "/home/mvpavlukhin/.conda/envs/speech2face/lib/python3.8/site-packages/urllib3/connectionpool.py", line 670, in urlopen
    httplib_response = self._make_request(
  File "/home/mvpavlukhin/.conda/envs/speech2face/lib/python3.8/site-packages/urllib3/connectionpool.py", line 381, in _make_request
    self._validate_conn(conn)
  File "/home/mvpavlukhin/.conda/envs/speech2face/lib/python3.8/site-packages/urllib3/connectionpool.py", line 978, in _validate_conn
    conn.connect()
  File "/home/mvpavlukhin/.conda/envs/speech2face/lib/python3.8/site-packages/urllib3/connection.py", line 309, in connect
    conn = self._new_conn()
  File "/home/mvpavlukhin/.conda/envs/speech2face/lib/python3.8/site-packages/urllib3/connection.py", line 164, in _new_conn
    raise ConnectTimeoutError(
urllib3.exceptions.ConnectTimeoutError: (<urllib3.connection.HTTPSConnection object at 0x7fc177fabb80>, 'Connection to api.wandb.ai timed out. (connect timeout=10)')

During handling of the above exception, another exception occurred:

Traceback (most recent call last):
  File "/home/mvpavlukhin/.conda/envs/speech2face/lib/python3.8/site-packages/requests/adapters.py", line 439, in send
    resp = conn.urlopen(
  File "/home/mvpavlukhin/.conda/envs/speech2face/lib/python3.8/site-packages/urllib3/connectionpool.py", line 726, in urlopen
    retries = retries.increment(
  File "/home/mvpavlukhin/.conda/envs/speech2face/lib/python3.8/site-packages/urllib3/util/retry.py", line 439, in increment
    raise MaxRetryError(_pool, url, error or ResponseError(cause))
urllib3.exceptions.MaxRetryError: HTTPSConnectionPool(host='api.wandb.ai', port=443): Max retries exceeded with url: /graphql (Caused by ConnectTimeoutError(<urllib3.connection.HTTPSConnection object at 0x7fc177fabb80>, 'Connection to api.wandb.ai timed out. (connect timeout=10)'))

During handling of the above exception, another exception occurred:

Traceback (most recent call last):
  File "/home/mvpavlukhin/.conda/envs/speech2face/lib/python3.8/site-packages/wandb/old/retry.py", line 96, in __call__
    result = self._call_fn(*args, **kwargs)
  File "/home/mvpavlukhin/.conda/envs/speech2face/lib/python3.8/site-packages/wandb/internal/internal_api.py", line 128, in execute
    return self.client.execute(*args, **kwargs)
  File "/home/mvpavlukhin/.conda/envs/speech2face/lib/python3.8/site-packages/wandb/vendor/gql-0.2.0/gql/client.py", line 52, in execute
    result = self._get_result(document, *args, **kwargs)
  File "/home/mvpavlukhin/.conda/envs/speech2face/lib/python3.8/site-packages/wandb/vendor/gql-0.2.0/gql/client.py", line 60, in _get_result
    return self.transport.execute(document, *args, **kwargs)
  File "/home/mvpavlukhin/.conda/envs/speech2face/lib/python3.8/site-packages/wandb/vendor/gql-0.2.0/gql/transport/requests.py", line 38, in execute
    request = requests.post(self.url, **post_args)
  File "/home/mvpavlukhin/.conda/envs/speech2face/lib/python3.8/site-packages/requests/api.py", line 119, in post
    return request('post', url, data=data, json=json, **kwargs)
  File "/home/mvpavlukhin/.conda/envs/speech2face/lib/python3.8/site-packages/requests/api.py", line 61, in request
    return session.request(method=method, url=url, **kwargs)
  File "/home/mvpavlukhin/.conda/envs/speech2face/lib/python3.8/site-packages/requests/sessions.py", line 530, in request
    resp = self.send(prep, **send_kwargs)
  File "/home/mvpavlukhin/.conda/envs/speech2face/lib/python3.8/site-packages/requests/sessions.py", line 643, in send
    r = adapter.send(request, **kwargs)
  File "/home/mvpavlukhin/.conda/envs/speech2face/lib/python3.8/site-packages/requests/adapters.py", line 504, in send
    raise ConnectTimeout(e, request=request)
requests.exceptions.ConnectTimeout: HTTPSConnectionPool(host='api.wandb.ai', port=443): Max retries exceeded with url: /graphql (Caused by ConnectTimeoutError(<urllib3.connection.HTTPSConnection object at 0x7fc177fabb80>, 'Connection to api.wandb.ai timed out. (connect timeout=10)'))
2020-11-30 00:48:08,886 INFO    MainThread:319870 [wandb_run.py:_atexit_cleanup():1238] got exitcode: 1
2020-11-30 00:48:08,938 INFO    MainThread:319870 [wandb_run.py:_restore():1210] restore
2020-11-30 00:48:08,938 INFO    MainThread:319870 [redirect.py:uninstall():215] uninstall start
2020-11-30 00:48:08,938 INFO    MainThread:319870 [redirect.py:_stop():264] _stop: stdout
2020-11-30 00:48:08,939 INFO    MainThread:319870 [redirect.py:_stop():270] _stop closed: stdout
2020-11-30 00:48:08,939 INFO    stdout    :319870 [redirect.py:_pipe_relay():119] relay done saw last write: stdout
2020-11-30 00:48:08,939 INFO    stdout    :319870 [redirect.py:_pipe_relay():135] relay done done: stdout
2020-11-30 00:48:08,950 INFO    MainThread:319870 [redirect.py:_stop():276] _stop joined: stdout
2020-11-30 00:48:08,950 INFO    MainThread:319870 [redirect.py:_stop():278] _stop rd closed: stdout
2020-11-30 00:48:08,950 INFO    MainThread:319870 [redirect.py:uninstall():219] uninstall done
2020-11-30 00:48:08,950 INFO    MainThread:319870 [redirect.py:uninstall():215] uninstall start
2020-11-30 00:48:08,951 INFO    MainThread:319870 [redirect.py:_stop():264] _stop: stderr
2020-11-30 00:48:08,951 INFO    MainThread:319870 [redirect.py:_stop():270] _stop closed: stderr
2020-11-30 00:48:08,951 INFO    stderr    :319870 [redirect.py:_pipe_relay():119] relay done saw last write: stderr
2020-11-30 00:48:08,951 INFO    stderr    :319870 [redirect.py:_pipe_relay():135] relay done done: stderr
2020-11-30 00:48:08,951 INFO    MainThread:319870 [redirect.py:_stop():276] _stop joined: stderr
2020-11-30 00:48:08,951 INFO    MainThread:319870 [redirect.py:_stop():278] _stop rd closed: stderr
2020-11-30 00:48:08,951 INFO    MainThread:319870 [redirect.py:uninstall():219] uninstall done
2020-11-30 00:48:09,081 INFO    MainThread:319870 [wandb_run.py:_wait_for_finish():1349] got exit ret: uuid: "4e616ea25e1e4a3c9c151c7b686c6910"

2020-11-30 00:48:11,087 INFO    MainThread:319870 [wandb_run.py:_wait_for_finish():1349] got exit ret: uuid: "dc358c5cc2f94aa4ab9bb507bbcb62d0"
response {
  poll_exit_response {
    done: true
    exit_result {
    }
  }
}

2020-11-30 00:48:14,345 INFO    MainThread:319870 [wandb_run.py:_show_summary():1477] rendering summary
2020-11-30 00:48:14,357 INFO    MainThread:319870 [wandb_run.py:_show_history():1515] rendering history
2020-11-30 00:48:14,371 INFO    MainThread:319870 [internal.py:handle_exit():137] Internal process exited
